Workbook

Sheet Сводка
A1: Советник: справедливые цены и сигналы
A2: ="Котировки на "&TEXT(Параметры!$B$5,"DD.MM.YYYY")&" · текущие цены — столбец D (жёлтый) · правила зон — на листе «Параметры»" -> Котировки на 24.10.2026 · текущие цены — столбец D (жёлтый) · правила зон — на листе «Параметры»
A4: Тикер | B4: Компания | C4: Метод | D4: Текущая цена, ₽ | E4: Справедливая, ₽ | F4: Зона покупки ≤, ₽ | G4: Приближается ≥, ₽ | H4: Цена продажи, ₽ | I4: До справедливой | J4: До продажи | K4: Статус | L4: Позиция, шт | M4: Стоимость, ₽ | N4: Доля | O4: Справедливая без мира, ₽ | P4: Прибавка от мира, ₽
A5: SBER | B5: Сбербанк | C5: Дивиденды (Гордон) | D5: 292.32 | E5: =SBER!$B$39 -> 547.65241 | F5: =SBER!$B$41 -> 421.69236 | G5: =SBER!$B$43 -> 613.91835 | H5: =SBER!$B$42 -> 646.22984 | I5: =IF(D5>0,E5/D5-1,0) -> 0.87346884 | J5: =IF(D5>0,H5/D5-1,0) -> 1.2106932 | K5: =IF(D5<=F5,"ЗОНА ПОКУПКИ",IF(D5>=H5,"ЦЕНА ПРОДАЖИ",IF(D5>=G5,"ПРИБЛИЖАЕТСЯ К ПРОДАЖЕ","ДЕРЖАТЬ"))) -> ЗОНА ПОКУПКИ | L5: =SUMIF(Портфели!$B:$B,A5,Портфели!$D:$D) -> 192 | M5: =L5*D5 -> 56125.44 | N5: =IF(Портфели!$G$18>0,M5/Портфели!$G$18,0) -> 0.2036149 | O5: =SBER!$B$33 -> 508.99281 | P5: =E5-O5 -> 38.659598
A6: PLZL | B6: Полюс | C6: EV/EBITDA от золота | D6: 1098.2 | E6: =PLZL!$B$38 -> 1610.6026 | F6: =PLZL!$B$40 -> 1240.164 | G6: =PLZL!$B$42 -> 1805.4856 | H6: =PLZL!$B$41 -> 1900.5111 | I6: =IF(D6>0,E6/D6-1,0) -> 0.46658408 | J6: =IF(D6>0,H6/D6-1,0) -> 0.73056922 | K6: =IF(D6<=F6,"ЗОНА ПОКУПКИ",IF(D6>=H6,"ЦЕНА ПРОДАЖИ",IF(D6>=G6,"ПРИБЛИЖАЕТСЯ К ПРОДАЖЕ","ДЕРЖАТЬ"))) -> ЗОНА ПОКУПКИ | L6: =SUMIF(Портфели!$B:$B,A6,Портфели!$D:$D) -> 41 | M6: =L6*D6 -> 45026.2 | N6: =IF(Портфели!$G$18>0,M6/Портфели!$G$18,0) -> 0.16334848 | O6: =PLZL!$B$32 -> 1288.8231 | P6: =E6-O6 -> 321.77956
A7: POSI | B7: Группа Позитив | C7: P/E на NIC 2027П | D7: 1176.8 | E7: =POSI!$B$30 -> 1672.9057 | F7: =POSI!$B$32 -> 1288.1374 | G7: =POSI!$B$34 -> 1875.3273 | H7: =POSI!$B$33 -> 1974.0287 | I7: =IF(D7>0,E7/D7-1,0) -> 0.4215718 | J7: =IF(D7>0,H7/D7-1,0) -> 0.67745472 | K7: =IF(D7<=F7,"ЗОНА ПОКУПКИ",IF(D7>=H7,"ЦЕНА ПРОДАЖИ",IF(D7>=G7,"ПРИБЛИЖАЕТСЯ К ПРОДАЖЕ","ДЕРЖАТЬ"))) -> ЗОНА ПОКУПКИ | L7: =SUMIF(Портфели!$B:$B,A7,Портфели!$D:$D) -> 32 | M7: =L7*D7 -> 37657.6 | N7: =IF(Портфели!$G$18>0,M7/Портфели!$G$18,0) -> 0.13661628 | O7: =POSI!$B$24 -> 1381.7508 | P7: =E7-O7 -> 291.15491
A8: PRMD | B8: Промомед | C8: EV/EBITDA 2027П | D8: 407 | E8: =PRMD!$B$32 -> 713.59824 | F8: =PRMD!$B$34 -> 549.47065 | G8: =PRMD!$B$36 -> 799.94363 | H8: =PRMD!$B$35 -> 842.04593 | I8: =IF(D8>0,E8/D8-1,0) -> 0.75331264 | J8: =IF(D8>0,H8/D8-1,0) -> 1.0689089 | K8: =IF(D8<=F8,"ЗОНА ПОКУПКИ",IF(D8>=H8,"ЦЕНА ПРОДАЖИ",IF(D8>=G8,"ПРИБЛИЖАЕТСЯ К ПРОДАЖЕ","ДЕРЖАТЬ"))) -> ЗОНА ПОКУПКИ | L8: =SUMIF(Портфели!$B:$B,A8,Портфели!$D:$D) -> 79 | M8: =L8*D8 -> 32153 | N8: =IF(Портфели!$G$18>0,M8/Портфели!$G$18,0) -> 0.11664639 | O8: =PRMD!$B$26 -> 584.65882 | P8: =E8-O8 -> 128.93942
A9: YDEX | B9: Яндекс | C9: EV/EBITDA 2027П | D9: 3400 | E9: =YDEX!$B$43 -> 12985.469 | F9: =YDEX!$B$45 -> 9998.8112 | G9: =YDEX!$B$47 -> 14556.711 | H9: =YDEX!$B$46 -> 15322.853 | I9: =IF(D9>0,E9/D9-1,0) -> 2.8192556 | J9: =IF(D9>0,H9/D9-1,0) -> 3.5067216 | K9: =IF(D9<=F9,"ЗОНА ПОКУПКИ",IF(D9>=H9,"ЦЕНА ПРОДАЖИ",IF(D9>=G9,"ПРИБЛИЖАЕТСЯ К ПРОДАЖЕ","ДЕРЖАТЬ"))) -> ЗОНА ПОКУПКИ | L9: =SUMIF(Портфели!$B:$B,A9,Портфели!$D:$D) -> 9 | M9: =L9*D9 -> 30600 | N9: =IF(Портфели!$G$18>0,M9/Портфели!$G$18,0) -> 0.11101233 | O9: =YDEX!$B$37 -> 11063.275 | P9: =E9-O9 -> 1922.1941
A10: MTSS | B10: МТС | C10: Выплаты акционерам (Гордон) | D10: 176.45 | E10: =MTSS!$B$42 -> 430.37534 | F10: =MTSS!$B$44 -> 331.38901 | G10: =MTSS!$B$46 -> 482.45076 | H10: =MTSS!$B$45 -> 507.8429 | I10: =IF(D10>0,E10/D10-1,0) -> 1.4390782 | J10: =IF(D10>0,H10/D10-1,0) -> 1.8781122 | K10: =IF(D10<=F10,"ЗОНА ПОКУПКИ",IF(D10>=H10,"ЦЕНА ПРОДАЖИ",IF(D10>=G10,"ПРИБЛИЖАЕТСЯ К ПРОДАЖЕ","ДЕРЖАТЬ"))) -> ЗОНА ПОКУПКИ | L10: =SUMIF(Портфели!$B:$B,A10,Портфели!$D:$D) -> 150 | M10: =L10*D10 -> 26467.5 | N10: =IF(Портфели!$G$18>0,M10/Портфели!$G$18,0) -> 0.096020226 | O10: =MTSS!$B$36 -> 370.74046 | P10: =E10-O10 -> 59.634876
A11: GAZP | B11: Газпром | C11: EV/EBITDA + опционы | D11: 114.75 | E11: =GAZP!$B$63 -> 144.70446 | F11: =GAZP!$B$65 -> 111.42244 | G11: =GAZP!$B$67 -> 162.2137 | H11: =GAZP!$B$66 -> 170.75127 | I11: =IF(D11>0,E11/D11-1,0) -> 0.26104108 | J11: =IF(D11>0,H11/D11-1,0) -> 0.48802847 | K11: =IF(D11<=F11,"ЗОНА ПОКУПКИ",IF(D11>=H11,"ЦЕНА ПРОДАЖИ",IF(D11>=G11,"ПРИБЛИЖАЕТСЯ К ПРОДАЖЕ","ДЕРЖАТЬ"))) -> ДЕРЖАТЬ | L11: =SUMIF(Портфели!$B:$B,A11,Портфели!$D:$D) -> 210 | M11: =L11*D11 -> 24097.5 | N11: =IF(Портфели!$G$18>0,M11/Портфели!$G$18,0) -> 0.087422212 | O11: =GAZP!$B$56 -> 114.95422 | P11: =E11-O11 -> 29.750245
A12: NLMK | B12: НЛМК | C12: EV/EBITDA цикла | D12: 76.44 | E12: =NLMK!$B$33 -> 106.97302 | F12: =NLMK!$B$35 -> 82.369229 | G12: =NLMK!$B$37 -> 119.91676 | H12: =NLMK!$B$36 -> 126.22817 | I12: =IF(D12>0,E12/D12-1,0) -> 0.39943779 | J12: =IF(D12>0,H12/D12-1,0) -> 0.65133659 | K12: =IF(D12<=F12,"ЗОНА ПОКУПКИ",IF(D12>=H12,"ЦЕНА ПРОДАЖИ",IF(D12>=G12,"ПРИБЛИЖАЕТСЯ К ПРОДАЖЕ","ДЕРЖАТЬ"))) -> ЗОНА ПОКУПКИ | L12: =SUMIF(Портфели!$B:$B,A12,Портфели!$D:$D) -> 270 | M12: =L12*D12 -> 20638.8 | N12: =IF(Портфели!$G$18>0,M12/Портфели!$G$18,0) -> 0.074874553 | O12: =NLMK!$B$27 -> 92.138149 | P12: =E12-O12 -> 14.834876
A13: BSPB | B13: Банк Санкт-Петербург | C13: Дивиденды (Гордон) | D13: 257.06 | E13: =BSPB!$B$30 -> 258.09106 | F13: =BSPB!$B$32 -> 198.73012 | G13: =BSPB!$B$34 -> 289.32008 | H13: =BSPB!$B$33 -> 304.54745 | I13: =IF(D13>0,E13/D13-1,0) -> 0.0040109644 | J13: =IF(D13>0,H13/D13-1,0) -> 0.18473294 | K13: =IF(D13<=F13,"ЗОНА ПОКУПКИ",IF(D13>=H13,"ЦЕНА ПРОДАЖИ",IF(D13>=G13,"ПРИБЛИЖАЕТСЯ К ПРОДАЖЕ","ДЕРЖАТЬ"))) -> ДЕРЖАТЬ | L13: =SUMIF(Портфели!$B:$B,A13,Портфели!$D:$D) -> 0 | M13: =L13*D13 -> 0 | N13: =IF(Портфели!$G$18>0,M13/Портфели!$G$18,0) -> 0 | O13: =BSPB!$B$24 -> 240.55424 | P13: =E13-O13 -> 17.536822
A14: Итого акции | M14: =SUM(M5:M13) -> 272766.04 | N14: =SUM(N5:N13) -> 0.98955537
A15: Как читать: «ДЕРЖАТЬ» — цена между зоной покупки и сигналом «приближается»; «ЗОНА ПОКУПКИ» — бумага заметно дешевле справедливой; «ПРИБЛИЖАЕТСЯ К ПРОДАЖЕ» / «ЦЕНА ПРОДАЖИ» — повод открыть модель и проверить тезис.
A16: Справедливая цена считается на листе эмитента. Меняйте синие вводные там — сводка пересчитается сама.
A17: Это аналитическая модель для ваших решений, а не индивидуальная инвестиционная рекомендация. Сделки бот не совершает.

Sheet Портфели
A1: Портфели
A2: Количество и средняя цена — со скриншотов брокеров (синие, обновляйте при сделках). Текущая цена подтягивается со «Сводки».
A4: Счёт | B4: Тикер | C4: Компания | D4: Кол-во, шт | E4: Средняя цена, ₽ | F4: Текущая цена, ₽ | G4: Стоимость, ₽ | H4: Вложено, ₽ | I4: Результат, ₽ | J4: Результат | K4: Доля в общем
A5: ИИС | B5: SBER | C5: Сбербанк | D5: 192 | E5: 286.95 | F5: =IFERROR(INDEX(Сводка!$D$5:$D$13,MATCH(B5,Сводка!$A$5:$A$13,0)),0) -> 292.32 | G5: =D5*F5 -> 56125.44 | H5: =D5*E5 -> 55094.4 | I5: =G5-H5 -> 1031.04 | J5: =IF(H5>0,I5/H5,0) -> 0.018714062 | K5: =IF($G$18>0,G5/$G$18,0) -> 0.2036149
A6: ИИС | B6: POSI | C6: Группа Позитив | D6: 32 | E6: 982.9 | F6: =IFERROR(INDEX(Сводка!$D$5:$D$13,MATCH(B6,Сводка!$A$5:$A$13,0)),0) -> 1176.8 | G6: =D6*F6 -> 37657.6 | H6: =D6*E6 -> 31452.8 | I6: =G6-H6 -> 6204.8 | J6: =IF(H6>0,I6/H6,0) -> 0.19727337 | K6: =IF($G$18>0,G6/$G$18,0) -> 0.13661628
A7: ИИС | B7: PRMD | C7: Промомед | D7: 79 | E7: 387.48 | F7: =IFERROR(INDEX(Сводка!$D$5:$D$13,MATCH(B7,Сводка!$A$5:$A$13,0)),0) -> 407 | G7: =D7*F7 -> 32153 | H7: =D7*E7 -> 30610.92 | I7: =G7-H7 -> 1542.08 | J7: =IF(H7>0,I7/H7,0) -> 0.050376794 | K7: =IF($G$18>0,G7/$G$18,0) -> 0.11664639
A8: ИИС | B8: YDEX | C8: Яндекс | D8: 9 | E8: 4193.7 | F8: =IFERROR(INDEX(Сводка!$D$5:$D$13,MATCH(B8,Сводка!$A$5:$A$13,0)),0) -> 3400 | G8: =D8*F8 -> 30600 | H8: =D8*E8 -> 37743.3 | I8: =G8-H8 -> -7143.3 | J8: =IF(H8>0,I8/H8,0) -> -0.18926008 | K8: =IF($G$18>0,G8/$G$18,0) -> 0.11101233
A9: ИИС | B9: MTSS | C9: МТС | D9: 150 | E9: 195.35 | F9: =IFERROR(INDEX(Сводка!$D$5:$D$13,MATCH(B9,Сводка!$A$5:$A$13,0)),0) -> 176.45 | G9: =D9*F9 -> 26467.5 | H9: =D9*E9 -> 29302.5 | I9: =G9-H9 -> -2835 | J9: =IF(H9>0,I9/H9,0) -> -0.096749424 | K9: =IF($G$18>0,G9/$G$18,0) -> 0.096020226
A10: Счёт 2 | B10: PLZL | C10: Полюс | D10: 41 | E10: 1135 | F10: =IFERROR(INDEX(Сводка!$D$5:$D$13,MATCH(B10,Сводка!$A$5:$A$13,0)),0) -> 1098.2 | G10: =D10*F10 -> 45026.2 | H10: =D10*E10 -> 46535 | I10: =G10-H10 -> -1508.8 | J10: =IF(H10>0,I10/H10,0) -> -0.032422907 | K10: =IF($G$18>0,G10/$G$18,0) -> 0.16334848
A11: Счёт 2 | B11: GAZP | C11: Газпром | D11: 210 | E11: 100.05 | F11: =IFERROR(INDEX(Сводка!$D$5:$D$13,MATCH(B11,Сводка!$A$5:$A$13,0)),0) -> 114.75 | G11: =D11*F11 -> 24097.5 | H11: =D11*E11 -> 21010.5 | I11: =G11-H11 -> 3087 | J11: =IF(H11>0,I11/H11,0) -> 0.14692654 | K11: =IF($G$18>0,G11/$G$18,0) -> 0.087422212
A12: Счёт 2 | B12: NLMK | C12: НЛМК | D12: 270 | E12: 71.71 | F12: =IFERROR(INDEX(Сводка!$D$5:$D$13,MATCH(B12,Сводка!$A$5:$A$13,0)),0) -> 76.44 | G12: =D12*F12 -> 20638.8 | H12: =D12*E12 -> 19361.7 | I12: =G12-H12 -> 1277.1 | J12: =IF(H12>0,I12/H12,0) -> 0.065960117 | K12: =IF($G$18>0,G12/$G$18,0) -> 0.074874553
A13: ИИС | B13: RUB | C13: Рубли на счёте | G13: 1015 | H13: =G13 -> 1015 | I13: =G13-H13 -> 0 | K13: =IF($G$18>0,G13/$G$18,0) -> 0.0036822718
A14: Счёт 2 | B14: RUB | C14: Рубли на счёте | G14: 1864.01 | H14: =G14 -> 1864.01 | I14: =G14-H14 -> 0 | K14: =IF($G$18>0,G14/$G$18,0) -> 0.0067623562
A16: ИИС | G16: =SUMIF($A$5:$A$14,"ИИС",G$5:G$14) -> 184018.54 | H16: =SUMIF($A$5:$A$14,"ИИС",H$5:H$14) -> 185218.92 | I16: =SUMIF($A$5:$A$14,"ИИС",I$5:I$14) -> -1200.38 | J16: =IF(H16>0,I16/H16,0) -> -0.0064808714 | K16: =IF($G$18>0,G16/$G$18,0) -> 0.6675924
A17: Счёт 2 | G17: =SUMIF($A$5:$A$14,"Счёт 2",G$5:G$14) -> 91626.51 | H17: =SUMIF($A$5:$A$14,"Счёт 2",H$5:H$14) -> 88771.21 | I17: =SUMIF($A$5:$A$14,"Счёт 2",I$5:I$14) -> 2855.3 | J17: =IF(H17>0,I17/H17,0) -> 0.032164707 | K17: =IF($G$18>0,G17/$G$18,0) -> 0.3324076
A18: ИТОГО по всем счетам | G18: =SUM(G5:G14) -> 275645.05 | H18: =SUM(H5:H14) -> 273990.13 | I18: =SUM(I5:I14) -> 1654.92 | J18: =IF(H18>0,I18/H18,0) -> 0.0060400716 | K18: =IF($G$18>0,G18/$G$18,0) -> 1
A20: «Вложено» и «Результат» — по средней цене текущих позиций (как показывает брокер), без учёта уже закрытых сделок и дивидендов. Рубли на счёте учтены как вложенные по номиналу (результат 0).

Sheet Параметры
A1: Глобальные параметры моделей
A2: Синий — вводные, которые можно менять; жёлтая заливка — главные рычаги. Все модели ссылаются сюда.
A4: Параметр | B4: Значение | C4: Ед. | D4: Источник / комментарий
A5: Дата котировок | B5: 46319 | D5: Цены в «Сводке» — со скриншотов брокеров 24.10.2026 (сессия выходного дня); дальше обновляет бот.
A6: Средняя ключевая ставка 2027 (прогноз ЦБ) | B6: 0.13 | C6: % | D6: ЦБ 23.10.2026 сохранил ставку 14% и повысил прогноз средней ставки на 2027 до 12,5–13,5% (было 10,5–12,5%); берём середину. Коммерсантъ, 23.10.2026: https://www.kommersant.ru/doc/9059054
A7: Премия за риск российских акций | B7: 0.06 | C7: % | D7: Допущение модели: надбавка за риск акций над безрисковой ставкой; типичный диапазон в оценках инвестдомов 5–7%.
A8: Доходность 10-летних ОФЗ (для сравнения) | B8: 0.166 | C8: % | D8: Длинные ОФЗ 26250–26254 ~16,6% (smart-lab, 23.10.2026); 10-летние 16,46% (Fomag, 18.09.2026). Модель берёт ставку ЦБ на 2027, а не ОФЗ: в ОФЗ заложена рыночная инфляция ~8%, а рост g в моделях — при инфляции ~4–5%. Проверка «по ОФЗ» — на листах SBER и MTSS.
A9: Базовая требуемая доходность акций | B9: =$B$6+$B$7 -> 0.19 | C9: % | D9: Ставка + премия. Используется в дивидендных моделях (Сбер, МТС) и как ориентир для мультипликаторов.
A10: Зона покупки: скидка к справедливой | B10: 0.23 | C10: % | D10: Цена ниже справедливой на эту величину — бот шлёт сигнал «зона покупки» (запас прочности долгосрочного инвестора).
A11: Цена продажи: премия к справедливой | B11: 0.18 | C11: % | D11: Продаём не на справедливой цене, а с запасом: хорошая компания растёт вместе с прибылью.
A12: Порог «приближается к продаже» | B12: 0.05 | C12: % | D12: За сколько процентов до цены продажи бот предупреждает заранее.
A13: Курс USD/RUB (прогноз на горизонт оценки) | B13: 85 | C13: ₽ | D13: Курс ЦБ на 24.10.2026 — 80,54 ₽; опрос аналитиков ЦБ (октябрь 2026): средний курс 2027 — 89,4 ₽. Берём 85 ₽ — середину. Влияет на Полюс и газовые опционы Газпрома.
A14: Цена золота (прогноз на горизонт оценки) | B14: 3800 | C14: $/унц | D14: Спот 23–24.10.2026 ~3 995 $/унц (пик ~5 595 $ в январе 2026). Берём 3 800 $ — ниже спота, с запасом. Ключевая вводная для Полюса.
A15: Мир: вероятность мира и снятия всех санкций | B15: 0.5 | C15: % | D15: Решение пользователя (25.10.2026): 50% — мир и снятие всех санкций в течение 5 лет. Прибавка от мира пропорциональна вероятности.
A16: Мир: лет до снятия санкций | B16: 5 | C16: лет | D16: К этому году рынок возвращается к оценкам компаний до 2022 года. Прибавка к цене приводится к сегодняшнему дню по ставке эмитента.
A17: ИИ: рынок генеративного ИИ в РФ в 2030 | B17: 778 | C17: млрд ₽ | D17: Onside / Just AI (февраль 2026): 58 млрд в 2025 → 778 млрд в 2030 (+68% в год); Just AI — заинтересованная сторона. AIANA (август 2026): весь рынок ИИ с оборудованием 316 млрд в 2025 → 830 млрд в 2030 (база), 1 120 млрд (оптимистичный). Иностранные модели в РФ ограничены — рынок делят российские игроки (Яндекс, Сбер, МТС, VK, Т-Банк).
A18: ИИ: лет до 2030 | B18: 4 | C18: лет | D18: ИИ-бизнес оценивается на 2030 год и дисконтируется к сегодняшнему дню по ставке эмитента.
A19: ИИ: OpenAI — оценка / годовая выручка | B19: 28 | C19: x | D19: Переговоры о раунде при оценке ~$1,4 трлн (Bloomberg, сентябрь 2026) / годовой темп выручки ~$50 млрд (Axios, октябрь 2026). Последний закрытый раунд — $852 млрд (март 2026). Компания убыточна: операционный убыток $20,9 млрд в 2025.
A20: ИИ: Anthropic — оценка / годовая выручка | B20: 14.8 | C20: x | D20: $965 млрд (раунд серии H, май 2026) / годовой темп выручки $65 млрд (июль 2026, Bloomberg/CNBC).
A21: ИИ: Alphabet — капитализация / выручка 2026П | B21: 8.1 | C21: x | D21: $3,88 трлн (24.10.2026, companiesmarketcap) / ~$480 млрд выручки 2026П (1К $109,9 млрд, 2К $119,8 млрд, рост 24%).
A22: ИИ: мультипликатор лидеров (среднее трёх) | B22: =AVERAGE($B$19,$B$20,$B$21) -> 16.966667 | C22: x | D22: Стоимость компании, делённая на годовую выручку. Применяется к ИИ-выручке Яндекса, Сбера и МТС в 2030 году.
A23: ИИ: поправка на стоимость денег в РФ | B23: 1 | C23: x | D23: 1,0 — российский ИИ-бизнес оценивается так же, как OpenAI, Anthropic и Alphabet (допущение пользователя). Остальной бизнес тех же компаний рынок РФ оценивает примерно в 5 раз дешевле американских аналогов (строка ниже). Поставьте 0,2, чтобы увидеть консервативный вариант.
A24: Для сравнения: скидка рынка РФ к США | B24: 0.2 | C24: x | D24: Яндекс ~3,7x EV/EBITDA 2026П против ~19–20x у Alphabet (капитализация $3,88 трлн, EBITDA 2026П ~$195 млрд — оценка). Используется только в строках проверки.

Sheet SBER
A1: SBER — Сбербанк: модель справедливой стоимости
A2: Метод: дивидендная модель (формула Гордона)
A3: Банк платит 50% прибыли, поэтому стоимость акции = будущий дивиденд / (требуемая доходность − рост дивиденда). Проверка — P/E при справедливой цене против исторической нормы Сбера 4–6x.
A4: Синий — вводные (меняйте их), чёрный — формулы, зелёный — ссылки на другие листы, жёлтый — главные рычаги модели.
A6: Показатель | B6: Значение | C6: Ед. | D6: Источник / комментарий
A7: ВВОДНЫЕ
A8: Чистая прибыль 2026П (МСФО) | B8: 1950 | C8: млрд ₽ | D8: 9М 2026 РСБУ: 1 501 млрд (+18,2% г/г), ROE 23,0% (Reuters, 09.10.2026); 1П 2026 МСФО: 1 019 млрд; цель менеджмента ROE 22%; аналитики ждут 1,9–2,0 трлн.
A9: Доля прибыли на дивиденды | B9: 0.5 | C9: % | D9: Дивполитика: 50% прибыли МСФО; сохраняется в стратегии 2027–2029.
A10: Акций всего (обыкн. + преф.) | B10: 22.587 | C10: млрд шт | D10: 21,587 млрд обыкн. + 1,0 млрд преф. Сверка: дивиденды за 2025 = 850,2 млрд ₽ / 37,64 ₽ = 22,59 млрд.
A11: Базовая требуемая доходность | B11: =Параметры!$B$9 -> 0.19 | C11: % | D11: Из «Параметров»: ставка ЦБ 2027 + премия за риск акций.
A12: Премия за специфический риск | B12: 0 | C12: % | D12: Сбер — эталон рынка, дополнительная премия не нужна.
A13: Долгосрочный рост дивиденда | B13: 0.08 | C13: % | D13: Номинальный рост: инфляция в долгую ~4–5% + реальный рост бизнеса ~3–4%.
A14: ИИ: рынок генеративного ИИ в РФ в 2030 | B14: =Параметры!$B$17 -> 778 | C14: млрд ₽ | D14: Из «Параметров».
A15: ИИ: доля компании на рынке в 2030 | B15: 0.4 | C15: % | D15: GigaChat — лидер в банках, страховании и госсекторе (банки и страхование — 20% рынка генИИ), облако Cloud.ru. Вместе с Яндексом делят большую часть рынка. Оценка модели.
A16: ИИ: мультипликатор лидеров (оценка / выручка) | B16: =Параметры!$B$22 -> 16.966667 | C16: x | D16: Из «Параметров»: среднее OpenAI, Anthropic, Alphabet.
A17: ИИ: поправка на стоимость денег в РФ | B17: =Параметры!$B$23 -> 1 | C17: x | D17: Из «Параметров»: 1,0 — как у американских лидеров.
A18: ИИ: лет до 2030 | B18: =Параметры!$B$18 -> 4 | C18: лет | D18: Из «Параметров».
A19: Мир: вероятность мира и снятия санкций | B19: =Параметры!$B$15 -> 0.5 | C19: % | D19: Из «Параметров».
A20: Мир: лет до снятия санкций | B20: =Параметры!$B$16 -> 5 | C20: лет | D20: Из «Параметров».
A21: Мир: P/E как до 2022 года | B21: 6 | C21: x | D21: P/E Сбера в 2017–2021 был ~5–7x (2019 ~6,7x, 2021 ~5x). Применяется к прибыли 2026П.
A22: Мир: рост показателя до года мира, % в год | B22: 0.08 | C22: % | D22: Как рост дивиденда.
A24: РАСЧЁТ
A25: Дивиденд за 2026 (выплата летом 2027) | B25: =$B$8*$B$9/$B$10 -> 43.166423 | C25: ₽/акц.
A26: Требуемая доходность | B26: =$B$11+$B$12 -> 0.19 | C26: %
A27: Справедливая дивдоходность (r − g) | B27: =$B$26-$B$13 -> 0.11 | C27: %
A28: Базовая цена = дивиденд / (r − g) | B28: =IF($B$27>0,$B$25/$B$27,0) -> 392.42203 | C28: ₽ | D28: Банк без отдельной оценки ИИ.
A29: ИИ: выручка компании в 2030 | B29: =$B$14*$B$15 -> 311.2 | C29: млрд ₽
A30: ИИ: стоимость ИИ-бизнеса в 2030 | B30: =$B$29*$B$16*$B$17 -> 5280.0267 | C30: млрд ₽ | D30: Выручка × мультипликатор лидеров × поправка РФ.
A31: ИИ: стоимость сегодня (дисконт до 2030) | B31: =$B$30/(1+$B$11)^$B$18 -> 2632.9843 | C31: млрд ₽
A32: ИИ: прибавка к цене акции | B32: =IF($B$10>0,$B$31/$B$10,0) -> 116.57078 | C32: ₽
A33: Справедливая цена без мира | B33: =$B$28+$B$32 -> 508.99281 | C33: ₽
A34: Мир: цена в мирном режиме на сегодняшних показателях | B34: =$B$21*$B$8/$B$10 -> 517.99708 | C34: ₽ | D34: Если бы рынок уже сегодня оценивал компанию как до 2022 года. Без ИИ-блока.
A35: Мир: прибавка к цене сегодня | B35: =$B$19*($B$34-$B$28)*((1+$B$22)/(1+$B$11))^$B$20 -> 38.659598 | C35: ₽ | D35: Вероятность × разница цен × рост показателя до года мира, приведённый к сегодняшнему дню.
A36: Справедливая цена с миром | B36: =$B$33+$B$35 -> 547.65241 | C36: ₽
A38: РЕЗУЛЬТАТ
A39: Справедливая цена | B39: =$B$36 -> 547.65241 | C39: ₽ | D39: Главный вывод модели
A40: Текущая цена | B40: =Сводка!$D$5 -> 292.32 | C40: ₽ | D40: Берётся со «Сводки» (столбец D)
A41: Зона покупки: цена не выше | B41: =$B$39*(1-Параметры!$B$10) -> 421.69236 | C41: ₽ | D41: Справедливая минус скидка из «Параметров»
A42: Цена продажи | B42: =$B$39*(1+Параметры!$B$11) -> 646.22984 | C42: ₽ | D42: Справедливая плюс премия из «Параметров»
A43: Сигнал «приближается к продаже» от | B43: =$B$42*(1-Параметры!$B$12) -> 613.91835 | C43: ₽ | D43: За сколько % до цены продажи бот предупреждает
...

Sheet PLZL
A1: PLZL — Полюс: модель справедливой стоимости
A2: Метод: EV/EBITDA 2027 от цены золота, себестоимости и курса, с дисконтом за паузу дивидендов
A3: EBITDA = добыча × (цена золота − денежная себестоимость TCC) − прочие расходы, в рублях по курсу, минус постоянные новые налоги. Стоимость = EBITDA × мультипликатор − чистый долг − разовый налог, минус дисконт за паузу дивидендов до 2030 и урезанную отчётность. Делим на акции в обращении (без 408 млн акций у дочерней компании).
A4: Синий — вводные (меняйте их), чёрный — формулы, зелёный — ссылки на другие листы, жёлтый — главные рычаги модели.
A6: Показатель | B6: Значение | C6: Ед. | D6: Источник / комментарий
A7: ВВОДНЫЕ
A8: Производство золота 2027 | B8: 2550 | C8: тыс. унц | D8: Гайденс 2026 и 2027: 2,5–2,6 млн унций (Коммерсантъ); 2025: 2 529 тыс. унций.
A9: Цена золота | B9: =Параметры!$B$14 -> 3800 | C9: $/унц | D9: Из «Параметров».
A10: Денежная себестоимость TCC | B10: 1000 | C10: $/унц | D10: 2025: $739; 1П 2026: $1 069 (+64%); прогноз 2026: $990–1 040 при золоте $4 000 (растёт вместе с ценой из‑за НДПИ).
A11: Прочие расходы, % выручки | B11: 0.06 | C11: % | D11: 2025: выручка $8 723 млн − TCC × продажи ≈ $6 850 млн против EBITDA $6 347 млн → ~6%.
A12: Курс USD/RUB | B12: =Параметры!$B$13 -> 85 | C12: ₽ | D12: Из «Параметров».
A13: Постоянные новые налоги в год (НДПИ) | B13: 0 | C13: млрд ₽ | D13: Сообщения противоречат друг другу: Т-Инвестиции оценивали рост НДПИ на золото в ~30 млрд за 2 года, Fomag пишет, что повышение не предлагается. Если подтвердится — поставьте ~15.
A14: Разовый налог на сверхдоходы за 2026 | B14: 25 | C14: млрд ₽ | D14: Законопроект Минфина (Интерфакс, 24.09.2026): 20% для золотодобытчиков с доходов 2026 года сверх базы 2025. БКС: ~25 млрд ₽ для Полюса. Разовый — вычитается как долг, а не из EBITDA каждого года.
A15: Справедливый EV/EBITDA | B15: 4.5 | C15: x | D15: Исторически Полюс стоил 6x+ как самый дешёвый производитель в мире; сейчас рынок даёт ~3x.
A16: Чистый долг | B16: 600 | C16: млрд ₽ | D16: 31.12.2025: 554,6 млрд (1,1x); на 30.06.2026 Велес оценивает $7,5 млрд. Капзатраты $2,2–2,5 млрд в год и Сухой Лог (~$6 млрд) не дают долгу снижаться.
A17: Дисконт за паузу дивидендов и прозрачность | B17: 0.35 | C17: % | D17: 08.07.2026 менеджмент рекомендовал не платить дивиденды до 2030 (−25% за день); с 1П 2026 отчётность урезана, EBITDA не раскрывается.
A18: Акций в обращении | B18: 950 | C18: млн шт | D18: Выпущено 1 360,7 млн, из них ~408 млн выкуплены дочерней «Полюс Красноярск» в 2023. Сверка: дивиденд 54 млрд ₽ / 56,8 ₽ = ~951 млн.
A19: Ставка дисконтирования | B19: =Параметры!$B$9 -> 0.19 | C19: % | D19: Из «Параметров».
A20: Мир: вероятность мира и снятия санкций | B20: =Параметры!$B$15 -> 0.5 | C20: % | D20: Из «Параметров».
A21: Мир: лет до снятия санкций | B21: =Параметры!$B$16 -> 5 | C21: лет | D21: Из «Параметров».
A22: Мир: EV/EBITDA как до 2022 года | B22: 7 | C22: x | D22: В 2019–2021 Полюс стоил ~7–9x EBITDA. Дисконт за паузу дивидендов сохраняем — мир его не отменяет.
A23: Мир: рост показателя до года мира, % в год | B23: 0.1 | C23: % | D23: Сухой Лог удваивает добычу к ~2030.
A25: РАСЧЁТ
A26: Выручка 2027П | B26: =$B$8*$B$9*$B$12/1000000 -> 823.65 | C26: млрд ₽
A27: EBITDA до новых налогов | B27: =($B$8*($B$9-$B$10)-$B$11*$B$8*$B$9)*$B$12/1000000 -> 557.481 | C27: млрд ₽
A28: EBITDA 2027П | B28: =$B$27-$B$13 -> 557.481 | C28: млрд ₽
A29: Справедливая стоимость бизнеса (EV) | B29: =$B$28*$B$15 -> 2508.6645 | C29: млрд ₽
A30: Капитал до дисконта | B30: =$B$29-$B$16-$B$14 -> 1883.6645 | C30: млрд ₽
A31: Капитал после дисконта | B31: =$B$30*(1-$B$17) -> 1224.3819 | C31: млрд ₽
A32: Справедливая цена без мира | B32: =IF($B$18>0,$B$31*1000/$B$18,0) -> 1288.8231 | C32: ₽
A33: Мир: цена в мирном режиме на сегодняшних показателях | B33: =((($B$8*($B$9-$B$10)-$B$11*$B$8*$B$9)*$B$12/1000000-$B$13)*$B$22-$B$16-$B$14)*(1-$B$17)*1000/$B$18 -> 2242.409 | C33: ₽ | D33: Если бы рынок уже сегодня оценивал компанию как до 2022 года.
A34: Мир: прибавка к цене сегодня | B34: =$B$20*($B$33-$B$32)*((1+$B$23)/(1+$B$19))^$B$21 -> 321.77956 | C34: ₽ | D34: Вероятность × разница цен × рост показателя до года мира, приведённый к сегодняшнему дню.
A35: Справедливая цена с миром | B35: =$B$32+$B$34 -> 1610.6026 | C35: ₽
A37: РЕЗУЛЬТАТ
A38: Справедливая цена | B38: =$B$35 -> 1610.6026 | C38: ₽ | D38: Главный вывод модели
A39: Текущая цена | B39: =Сводка!$D$6 -> 1098.2 | C39: ₽ | D39: Берётся со «Сводки» (столбец D)
A40: Зона покупки: цена не выше | B40: =$B$38*(1-Параметры!$B$10) -> 1240.164 | C40: ₽ | D40: Справедливая минус скидка из «Параметров»
A41: Цена продажи | B41: =$B$38*(1+Параметры!$B$11) -> 1900.5111 | C41: ₽ | D41: Справедливая плюс премия из «Параметров»
A42: Сигнал «приближается к продаже» от | B42: =$B$41*(1-Параметры!$B$12) -> 1805.4856 | C42: ₽ | D42: За сколько % до цены продажи бот предупреждает
A43: Потенциал до справедливой | B43: =IF($B$39>0,$B$38/$B$39-1,0) -> 0.46658408 | C43: %
...

Sheet POSI
A1: POSI — Группа Позитив: модель справедливой стоимости
A2: Метод: P/E на прогноз скорректированной прибыли (NIC) 2027 года
A3: Positive платит дивиденды из NIC — чистой прибыли с поправкой на капитализированные расходы. Стоимость = NIC 2027 × справедливый P/E / число акций. NIC строим от оплаченных отгрузок — главного показателя компании.
A4: Синий — вводные (меняйте их), чёрный — формулы, зелёный — ссылки на другие листы, жёлтый — главные рычаги модели.
A6: Показатель | B6: Значение | C6: Ед. | D6: Источник / комментарий
A7: ВВОДНЫЕ
A8: Оплаченные отгрузки 2026П | B8: 41 | C8: млрд ₽ | D8: Гайденс 40–45 млрд (подтверждён 27.07 и 16.10.2026); 1П: 10,7 млрд (+45%), прогноз 3К 6,75 млрд → на 4 кв. для 41 млрд нужно 23,6 млрд (57% года; в 2025 было ~65%). Берём нижнюю половину: в 2025 предварительные 35 млрд стали 33,6.
A9: Рост отгрузок 2027 | B9: 0.2 | C9: % | D9: Рынок ИБ растёт в 3–4 раза быстрее ИТ; воронка продаж >60 млрд ₽ (июль 2026). Берём 20% — ниже роста 2025 (+40%).
A10: Маржа NIC к отгрузкам | B10: 0.2 | C10: % | D10: 2025: 8% (2,7 / 33,6 млрд); цель компании — приблизиться к 30%; расходы 2026 заморожены на уровне 2025. Берём 20%.
A11: Справедливый P/E | B11: 10 | C11: x | D11: Требуемая доходность 19% и выплата 50–100% NIC дают ~8x для зрелого бизнеса; +2x за рост 20% в ближайшие годы.
A12: Акций в обращении | B12: 71.214 | C12: млн шт | D12: Сверка: дивиденд 1 999,7 млн ₽ / 28,08 ₽ = 71,214 млн акций; × 1176 ₽ = 83,8 млрд ₽.
A13: Чистый долг (для проверки) | B13: 12.5 | C13: млрд ₽ | D13: На 30.06.2026, ЧД/EBITDA LTM 0,8x (год назад 2,33x); весь долг — облигации.
A14: Ставка дисконтирования | B14: =Параметры!$B$9 -> 0.19 | C14: % | D14: Из «Параметров».
A15: Мир: вероятность мира и снятия санкций | B15: =Параметры!$B$15 -> 0.5 | C15: % | D15: Из «Параметров».
A16: Мир: лет до снятия санкций | B16: =Параметры!$B$16 -> 5 | C16: лет | D16: Из «Параметров».
A17: Мир: P/E после снятия санкций | B17: 15 | C17: x | D17: До 2022 российские IT-компании стоили 20–30x прибыли, мировые лидеры кибербезопасности — 40x+. Берём 15x: после снятия санкций могут вернуться иностранные вендоры.
A18: Мир: рост показателя до года мира, % в год | B18: 0.15 | C18: % | D18: Рост отгрузок и NIC в среднем за 5 лет.
A20: РАСЧЁТ
A21: Оплаченные отгрузки 2027П | B21: =$B$8*(1+$B$9) -> 49.2 | C21: млрд ₽
A22: NIC 2027П | B22: =$B$21*$B$10 -> 9.84 | C22: млрд ₽
A23: Стоимость акционерного капитала | B23: =$B$22*$B$11 -> 98.4 | C23: млрд ₽
A24: Справедливая цена без мира | B24: =IF($B$12>0,$B$23*1000/$B$12,0) -> 1381.7508 | C24: ₽
A25: Мир: цена в мирном режиме на сегодняшних показателях | B25: =$B$8*(1+$B$9)*$B$10*$B$17*1000/$B$12 -> 2072.6262 | C25: ₽ | D25: Если бы рынок уже сегодня оценивал компанию как до 2022 года.
A26: Мир: прибавка к цене сегодня | B26: =$B$15*($B$25-$B$24)*((1+$B$18)/(1+$B$14))^$B$16 -> 291.15491 | C26: ₽ | D26: Вероятность × разница цен × рост показателя до года мира, приведённый к сегодняшнему дню.
A27: Справедливая цена с миром | B27: =$B$24+$B$26 -> 1672.9057 | C27: ₽
A29: РЕЗУЛЬТАТ
A30: Справедливая цена | B30: =$B$27 -> 1672.9057 | C30: ₽ | D30: Главный вывод модели
A31: Текущая цена | B31: =Сводка!$D$7 -> 1176.8 | C31: ₽ | D31: Берётся со «Сводки» (столбец D)
A32: Зона покупки: цена не выше | B32: =$B$30*(1-Параметры!$B$10) -> 1288.1374 | C32: ₽ | D32: Справедливая минус скидка из «Параметров»
A33: Цена продажи | B33: =$B$30*(1+Параметры!$B$11) -> 1974.0287 | C33: ₽ | D33: Справедливая плюс премия из «Параметров»
A34: Сигнал «приближается к продаже» от | B34: =$B$33*(1-Параметры!$B$12) -> 1875.3273 | C34: ₽ | D34: За сколько % до цены продажи бот предупреждает
A35: Потенциал до справедливой | B35: =IF($B$31>0,$B$30/$B$31-1,0) -> 0.4215718 | C35: %
A36: До цены продажи | B36: =IF($B$31>0,$B$33/$B$31-1,0) -> 0.67745472 | C36: %
A37: Статус | B37: =IF($B$31<=$B$32,"ЗОНА ПОКУПКИ",IF($B$31>=$B$33,"ЦЕНА ПРОДАЖИ",IF($B$31>=$B$34,"ПРИБЛИЖАЕТСЯ К ПРОДАЖЕ","ДЕРЖАТЬ"))) -> ЗОНА ПОКУПКИ | D37: Слом тезиса — отдельный сигнал, см. ниже
A39: ПЕРЕКРЁСТНАЯ ПРОВЕРКА
A40: P/E на NIC 2027П при текущей цене | B40: =IF($B$22>0,$B$31*$B$12/1000/$B$22,0) -> 8.5167312 | C40: x
A41: Потенциальный дивиденд за 2027 (50% NIC) | B41: =$B$22*0.5*1000/$B$12 -> 69.087539 | C41: ₽ | D41: Политика: 50–100% NIC при ЧД/EBITDA ≤ 2,5x.
A42: Медиана целей 6 брокеров | B42: =1475 -> 1475 | C42: ₽ | D42: 1300–2000 ₽: Эйлер 2000, Альфа 1990, ПСБ 1550, Freedom 1400, Сбер CIB 1350, Т-Инвестиции ~1300.
A44: ЧУВСТВИТЕЛЬНОСТЬ СПРАВЕДЛИВОЙ ЦЕНЫ, ₽: строки — P/E, столбцы — маржа NIC
A45: P/E \ маржа NIC | B45: 0.12 | C45: 0.16 | D45: 0.2 | E45: 0.24 | F45: 0.28
...

Sheet PRMD
A1: PRMD — Промомед: модель справедливой стоимости
A2: Метод: EV/EBITDA на прогноз 2027 года
A3: Компания роста без значимых дивидендов: стоимость бизнеса = EBITDA 2027 × справедливый мультипликатор, минус чистый долг, делим на число акций. Проверка — P/E при справедливой цене и сравнение с консенсусом аналитиков.
A4: Синий — вводные (меняйте их), чёрный — формулы, зелёный — ссылки на другие листы, жёлтый — главные рычаги модели.
A6: Показатель | B6: Значение | C6: Ед. | D6: Источник / комментарий
A7: ВВОДНЫЕ
A8: Выручка 2026П | B8: 60.2 | C8: млрд ₽ | D8: Гайденс: рост не ниже 60% к 37,6 млрд за 2025 (подтверждён 31.08 и в октябре 2026). 1П 2026: 22,8 млрд (+76%). АТОН, Ведомости, ABN 06.10.2026.
A9: Рост выручки 2027 | B9: 0.35 | C9: % | D9: CFO ждёт ~40% в год в 2027–2029 (ABN, 06.10.2026). Берём 35%: тирзепатид в РФ не защищён патентом, на рынок выходят Герофарм и ПСК Фарма.
A10: Рентабельность EBITDA 2027 | B10: 0.4 | C10: % | D10: 2025: 41%; 1П 2026: 34%; гайденс 2026 ~45%. Берём середину 40%.
A11: Справедливый EV/EBITDA | B11: 5 | C11: x | D11: Сейчас рынок даёт ~3,7x на 2027П. 5x — умеренная оценка для роста 35%+ с дисконтом за концентрацию на одном препарате и free-float 8,5%.
A12: Чистый долг на конец 2026П | B12: 38.3 | C12: млрд ₽ | D12: 30.06.2026: 33,3 млрд, ЧД/EBITDA 1,79x (АТОН); FCF 1П ≈ −5 млрд (Т-Инвестиции), во 2П ждём столько же → ~38 млрд к концу года. Положительный FCF компания ждёт в 2027.
A13: Акций в обращении | B13: 212.5 | C13: млн шт | D13: 212,5 млн обыкн. акций (investfunds); 212,5 × 407 ₽ = 86,5 млрд ₽ капитализации.
A14: Чистая рентабельность 2027 (для проверки) | B14: 0.16 | C14: % | D14: 2025: 19% (7,2 / 37,6 млрд); 1П 2026: 11% из‑за процентов. Берём 16%.
A15: Ставка дисконтирования | B15: =Параметры!$B$9 -> 0.19 | C15: % | D15: Из «Параметров».
A16: Мир: вероятность мира и снятия санкций | B16: =Параметры!$B$15 -> 0.5 | C16: % | D16: Из «Параметров».
A17: Мир: лет до снятия санкций | B17: =Параметры!$B$16 -> 5 | C17: лет | D17: Из «Параметров».
A18: Мир: EV/EBITDA после снятия санкций | B18: 7 | C18: x | D18: Мировые производители дженериков ~8–10x EBITDA; истории до 2022 нет (IPO 2024). Берём 7x.
A19: Мир: рост показателя до года мира, % в год | B19: 0.15 | C19: % | D19: Рост 35%+ не продлится 5 лет; берём 15% в среднем.
A21: РАСЧЁТ
A22: Выручка 2027П | B22: =$B$8*(1+$B$9) -> 81.27 | C22: млрд ₽
A23: EBITDA 2027П | B23: =$B$22*$B$10 -> 32.508 | C23: млрд ₽
A24: Справедливая стоимость бизнеса (EV) | B24: =$B$23*$B$11 -> 162.54 | C24: млрд ₽
A25: Стоимость акционерного капитала | B25: =$B$24-$B$12 -> 124.24 | C25: млрд ₽
A26: Справедливая цена без мира | B26: =IF($B$13>0,$B$25*1000/$B$13,0) -> 584.65882 | C26: ₽
A27: Мир: цена в мирном режиме на сегодняшних показателях | B27: =($B$8*(1+$B$9)*$B$10*$B$18-$B$12)*1000/$B$13 -> 890.61647 | C27: ₽ | D27: Если бы рынок уже сегодня оценивал компанию как до 2022 года.
A28: Мир: прибавка к цене сегодня | B28: =$B$16*($B$27-$B$26)*((1+$B$19)/(1+$B$15))^$B$17 -> 128.93942 | C28: ₽ | D28: Вероятность × разница цен × рост показателя до года мира, приведённый к сегодняшнему дню.
A29: Справедливая цена с миром | B29: =$B$26+$B$28 -> 713.59824 | C29: ₽
A31: РЕЗУЛЬТАТ
A32: Справедливая цена | B32: =$B$29 -> 713.59824 | C32: ₽ | D32: Главный вывод модели
A33: Текущая цена | B33: =Сводка!$D$8 -> 407 | C33: ₽ | D33: Берётся со «Сводки» (столбец D)
A34: Зона покупки: цена не выше | B34: =$B$32*(1-Параметры!$B$10) -> 549.47065 | C34: ₽ | D34: Справедливая минус скидка из «Параметров»
A35: Цена продажи | B35: =$B$32*(1+Параметры!$B$11) -> 842.04593 | C35: ₽ | D35: Справедливая плюс премия из «Параметров»
A36: Сигнал «приближается к продаже» от | B36: =$B$35*(1-Параметры!$B$12) -> 799.94363 | C36: ₽ | D36: За сколько % до цены продажи бот предупреждает
A37: Потенциал до справедливой | B37: =IF($B$33>0,$B$32/$B$33-1,0) -> 0.75331264 | C37: %
A38: До цены продажи | B38: =IF($B$33>0,$B$35/$B$33-1,0) -> 1.0689089 | C38: %
A39: Статус | B39: =IF($B$33<=$B$34,"ЗОНА ПОКУПКИ",IF($B$33>=$B$35,"ЦЕНА ПРОДАЖИ",IF($B$33>=$B$36,"ПРИБЛИЖАЕТСЯ К ПРОДАЖЕ","ДЕРЖАТЬ"))) -> ЗОНА ПОКУПКИ | D39: Слом тезиса — отдельный сигнал, см. ниже
A41: ПЕРЕКРЁСТНАЯ ПРОВЕРКА
A42: Чистая прибыль 2027П | B42: =$B$22*$B$14 -> 13.0032 | C42: млрд ₽
A43: P/E 2027П при справедливой цене | B43: =IF($B$42>0,$B$32*$B$13/1000/$B$42,0) -> 11.661716 | C43: x | D43: Для роста 35% разумно 8–12x.
A44: EV/EBITDA 2027П при текущей цене | B44: =IF($B$23>0,($B$33*$B$13/1000+$B$12)/$B$23,0) -> 3.8386705 | C44: x
...

Sheet YDEX
A1: YDEX — Яндекс: модель справедливой стоимости
A2: Метод: EV/EBITDA на прогноз 2027 года
A3: Компания роста с крупными капзатратами на ИИ и дата-центры. Стоимость бизнеса = (скорр. EBITDA 2027 − выплаты сотрудникам акциями) × мультипликатор; вычитаем чистый долг и разовый ущерб от атак на ЦОДы, делим на акции в обращении. Выплаты акциями вычтены из EBITDA, поэтому новые акции для сотрудников второй раз не учитываются.
A4: Синий — вводные (меняйте их), чёрный — формулы, зелёный — ссылки на другие листы, жёлтый — главные рычаги модели.
A6: Показатель | B6: Значение | C6: Ед. | D6: Источник / комментарий
A7: ВВОДНЫЕ
A8: Скорр. EBITDA 2026П | B8: 350 | C8: млрд ₽ | D8: Гайденс ~350 млрд, подтверждён 29.07.2026; 1П 2026: 162,2 млрд (маржа 21,4%), менеджмент ждёт ускорения во 2П.
A9: Рост EBITDA 2027 | B9: 0.15 | C9: % | D9: Гайденса на 2027 нет; выручка 2026 растёт ~20%, Совкомбанк ждёт замедления до ~12%. Берём 15%.
A10: Выплаты сотрудникам акциями в год | B10: 40 | C10: млрд ₽ | D10: Скорр. EBITDA их не включает, а расход постоянный: 18,3 млрд за 1П 2026 → ~37 млрд за 2026, ~40 млрд в 2027.
A11: Справедливый EV/(EBITDA − выплаты акциями) 2027П | B11: 4.5 | C11: x | D11: Рынок сейчас даёт ~3,6x на ту же базу 2027 года. 4,5x — премия ~25% за рост 15%+ и снижение ставки к 2028 (ЦБ: 9–10%). Меньше, чем у Промомеда (рост 35%).
A12: Скорр. чистый долг | B12: 7 | C12: млрд ₽ | D12: По данным компании на 30.06.2026 (0,02x LTM EBITDA): деньги 296 млрд, долг 277 млрд плюс долгосрочная аренда, которую компания включает в скорр. долг.
A13: Разовый ущерб от атак на ЦОДы | B13: 20 | C13: млрд ₽ | D13: По оценке пользователя: ~20 млрд ₽. Атаки 8–11.10.2026 (Сасово, Владимир, Калуга); компания ущерб не раскрыла, облако — 2–4% выручки. Уточнится в отчёте за 3К (29.10.2026).
A14: Акций в обращении | B14: 383 | C14: млн шт | D14: Выпущено 396,9 млн, из них ~15 млн у компании (выкуп и пул для сотрудников); в обращении 382,1 млн (средневзвешенно за 1П 2026, пресс-релиз 2К26). 11 млн новых акций (ноябрь 2026) — это и есть выплаты сотрудникам, они уже вычтены из EBITDA.
A15: Скорр. чистая прибыль 2027П (для проверки) | B15: 205 | C15: млрд ₽ | D15: 1П 2026: 82,2 млрд; 2026П ~180 млрд, +15% в 2027.
A16: Ставка дисконтирования | B16: =Параметры!$B$9 -> 0.19 | C16: % | D16: Из «Параметров».
A17: ИИ: рынок генеративного ИИ в РФ в 2030 | B17: =Параметры!$B$17 -> 778 | C17: млрд ₽ | D17: Из «Параметров».
A18: ИИ: доля компании на рынке в 2030 | B18: 0.4 | C18: % | D18: Алиса и YandexGPT — лидер в потребительском ИИ, Yandex Cloud — крупнейшее облако с ИИ-сервисами. Вместе со Сбером делят большую часть рынка. Оценка модели. Пересечение с базой: сегодняшняя ИИ-выручка уже есть в EBITDA, но она мала относительно рынка 2030.
A19: ИИ: мультипликатор лидеров (оценка / выручка) | B19: =Параметры!$B$22 -> 16.966667 | C19: x | D19: Из «Параметров»: среднее OpenAI, Anthropic, Alphabet.
A20: ИИ: поправка на стоимость денег в РФ | B20: =Параметры!$B$23 -> 1 | C20: x | D20: Из «Параметров»: 1,0 — как у американских лидеров.
A21: ИИ: лет до 2030 | B21: =Параметры!$B$18 -> 4 | C21: лет | D21: Из «Параметров».
A22: Мир: вероятность мира и снятия санкций | B22: =Параметры!$B$15 -> 0.5 | C22: % | D22: Из «Параметров».
A23: Мир: лет до снятия санкций | B23: =Параметры!$B$16 -> 5 | C23: лет | D23: Из «Параметров».
A24: Мир: EV/(EBITDA − выплаты акциями) после снятия санкций | B24: 10 | C24: x | D24: До 2022 Яндекс стоил 15–20x скорр. EBITDA (листинг в США); мировые интернет-компании ~12–15x. Берём 10x. ИИ-блок не переоцениваем — он уже по мультипликаторам США.
A25: Мир: рост показателя до года мира, % в год | B25: 0.12 | C25: % | D25: Рост EBITDA в среднем за 5 лет.
A27: РАСЧЁТ
A28: Скорр. EBITDA 2027П | B28: =$B$8*(1+$B$9) -> 402.5 | C28: млрд ₽
A29: EBITDA 2027П после выплат акциями | B29: =$B$28-$B$10 -> 362.5 | C29: млрд ₽
A30: Справедливая стоимость бизнеса (EV) | B30: =$B$29*$B$11 -> 1631.25 | C30: млрд ₽
A31: Стоимость акционерного капитала | B31: =$B$30-$B$12-$B$13 -> 1604.25 | C31: млрд ₽
A32: Базовая цена (без отдельной оценки ИИ) | B32: =IF($B$14>0,$B$31*1000/$B$14,0) -> 4188.6423 | C32: ₽
A33: ИИ: выручка компании в 2030 | B33: =$B$17*$B$18 -> 311.2 | C33: млрд ₽
A34: ИИ: стоимость ИИ-бизнеса в 2030 | B34: =$B$33*$B$19*$B$20 -> 5280.0267 | C34: млрд ₽ | D34: Выручка × мультипликатор лидеров × поправка РФ.
A35: ИИ: стоимость сегодня (дисконт до 2030) | B35: =$B$34/(1+$B$16)^$B$21 -> 2632.9843 | C35: млрд ₽
A36: ИИ: прибавка к цене акции | B36: =IF($B$14>0,$B$35*1000/$B$14,0) -> 6874.6327 | C36: ₽
A37: Справедливая цена без мира | B37: =$B$32+$B$36 -> 11063.275 | C37: ₽
A38: Мир: цена в мирном режиме на сегодняшних показателях | B38: =(($B$8*(1+$B$9)-$B$10)*$B$24-$B$12-$B$13)*1000/$B$14 -> 9394.2559 | C38: ₽ | D38: Если бы рынок уже сегодня оценивал компанию как до 2022 года. Без ИИ-блока.
A39: Мир: прибавка к цене сегодня | B39: =$B$22*($B$38-$B$32)*((1+$B$25)/(1+$B$16))^$B$23 -> 1922.1941 | C39: ₽ | D39: Вероятность × разница цен × рост показателя до года мира, приведённый к сегодняшнему дню.
A40: Справедливая цена с миром | B40: =$B$37+$B$39 -> 12985.469 | C40: ₽
A42: РЕЗУЛЬТАТ
A43: Справедливая цена | B43: =$B$40 -> 12985.469 | C43: ₽ | D43: Главный вывод модели
...

Sheet MTSS
A1: MTSS — МТС: модель справедливой стоимости
A2: Метод: модель денежных выплат акционерам (Гордон: дивиденды + выкуп акций)
A3: С 2027 года МТС возвращает акционерам не меньше 70 млрд ₽ в год: 70% дивидендами, 30% выкупом акций. Стоимость акции = выплаты на акцию / (требуемая доходность − рост). Требуемая доходность выше, чем у Сбера: большой долг и политика только на два года.
A4: Синий — вводные (меняйте их), чёрный — формулы, зелёный — ссылки на другие листы, жёлтый — главные рычаги модели.
A6: Показатель | B6: Значение | C6: Ед. | D6: Источник / комментарий
A7: ВВОДНЫЕ
A8: Выплаты акционерам в год (2027–2028) | B8: 70 | C8: млрд ₽ | D8: Политика от 15.09.2026: до 20% OIBDA, цель не менее 70 млрд ₽ в год; 70% дивиденды, 30% байбек; выплаты 3 раза в год, первая — январь 2027 за 9М 2026.
A9: Доля дивидендов в выплатах | B9: 0.7 | C9: % | D9: Остальные 30% — выкуп акций.
A10: Акций выпущено | B10: 1.9984 | C10: млрд шт | D10: 1 998 381 575 акций; дивиденд 35 ₽ = 69,9 млрд ₽ выплачивался на весь выпуск.
A11: Базовая требуемая доходность | B11: =Параметры!$B$9 -> 0.19 | C11: % | D11: Из «Параметров».
A12: Премия за специфический риск | B12: 0.02 | C12: % | D12: Чистый долг с арендой ~645 млрд ₽ (2,1x OIBDA), политика выплат только на 2027–2028, зависимость АФК «Система» от дивидендов.
A13: Долгосрочный рост выплат | B13: 0.04 | C13: % | D13: OIBDA растёт на 13–17%, но выплаты привязаны к фиксированной цели и съедаются капзатратами и процентами; берём 4%.
A14: Чистый долг с арендой (для проверки) | B14: 645.2 | C14: млрд ₽ | D14: На 30.06.2026 (Market Power, 2,13x OIBDA).
A15: OIBDA 2026П (для проверки) | B15: 325 | C15: млрд ₽ | D15: 1П 2026: 159,3 млрд (+17%); второе полугодие сезонно сильнее.
A16: ИИ: рынок генеративного ИИ в РФ в 2030 | B16: =Параметры!$B$17 -> 778 | C16: млрд ₽ | D16: Из «Параметров».
A17: ИИ: доля компании на рынке в 2030 | B17: 0.05 | C17: % | D17: MWS AI: цель ~1 млрд ₽ выручки в 2026 (~2% рынка генИИ); MWS (облака и ИИ) — 63,8 млрд ₽ выручки в 2025, рост MWS AI +60%. Оценка модели.
A18: ИИ: мультипликатор лидеров (оценка / выручка) | B18: =Параметры!$B$22 -> 16.966667 | C18: x | D18: Из «Параметров»: среднее OpenAI, Anthropic, Alphabet.
A19: ИИ: поправка на стоимость денег в РФ | B19: =Параметры!$B$23 -> 1 | C19: x | D19: Из «Параметров»: 1,0 — как у американских лидеров.
A20: ИИ: лет до 2030 | B20: =Параметры!$B$18 -> 4 | C20: лет | D20: Из «Параметров».
A21: Мир: вероятность мира и снятия санкций | B21: =Параметры!$B$15 -> 0.5 | C21: % | D21: Из «Параметров».
A22: Мир: лет до снятия санкций | B22: =Параметры!$B$16 -> 5 | C22: лет | D22: Из «Параметров».
A23: Мир: EV/OIBDA как до 2022 года | B23: 4.5 | C23: x | D23: МТС в 2017–2021 стоил ~4,5–5x OIBDA (акция 250–350 ₽). Применяется к OIBDA 2026П с нынешним долгом.
A24: Мир: рост показателя до года мира, % в год | B24: 0.07 | C24: % | D24: OIBDA сейчас растёт на 13–17%, к 2031 рост замедлится.
A26: РАСЧЁТ
A27: Выплаты на акцию в год | B27: =$B$8/$B$10 -> 35.028022 | C27: ₽/акц.
A28: из них дивиденд | B28: =$B$27*$B$9 -> 24.519616 | C28: ₽/акц.
A29: Требуемая доходность | B29: =$B$11+$B$12 -> 0.21 | C29: %
A30: Справедливая доходность выплат (r − g) | B30: =$B$29-$B$13 -> 0.17 | C30: %
A31: Базовая цена = выплаты / (r − g) | B31: =IF($B$30>0,$B$27/$B$30,0) -> 206.04719 | C31: ₽ | D31: Телеком без отдельной оценки ИИ.
A32: ИИ: выручка компании в 2030 | B32: =$B$16*$B$17 -> 38.9 | C32: млрд ₽
A33: ИИ: стоимость ИИ-бизнеса в 2030 | B33: =$B$32*$B$18*$B$19 -> 660.00333 | C33: млрд ₽ | D33: Выручка × мультипликатор лидеров × поправка РФ.
A34: ИИ: стоимость сегодня (дисконт до 2030) | B34: =$B$33/(1+$B$11)^$B$20 -> 329.12304 | C34: млрд ₽
A35: ИИ: прибавка к цене акции | B35: =IF($B$10>0,$B$34/$B$10,0) -> 164.69327 | C35: ₽
A36: Справедливая цена без мира | B36: =$B$31+$B$35 -> 370.74046 | C36: ₽
A37: Мир: цена в мирном режиме на сегодняшних показателях | B37: =($B$23*$B$15-$B$14)/$B$10 -> 408.97718 | C37: ₽ | D37: Если бы рынок уже сегодня оценивал компанию как до 2022 года. Без ИИ-блока.
A38: Мир: прибавка к цене сегодня | B38: =$B$21*($B$37-$B$31)*((1+$B$24)/(1+$B$11))^$B$22 -> 59.634876 | C38: ₽ | D38: Вероятность × разница цен × рост показателя до года мира, приведённый к сегодняшнему дню.
A39: Справедливая цена с миром | B39: =$B$36+$B$38 -> 430.37534 | C39: ₽
A41: РЕЗУЛЬТАТ
A42: Справедливая цена | B42: =$B$39 -> 430.37534 | C42: ₽ | D42: Главный вывод модели
A43: Текущая цена | B43: =Сводка!$D$10 -> 176.45 | C43: ₽ | D43: Берётся со «Сводки» (столбец D)
...

Sheet GAZP
A1: GAZP — Газпром: модель справедливой стоимости
A2: Метод: EV/EBITDA на нормализованную EBITDA + два опциона: «Северные потоки» и «Сила Байкала»
A3: База: нормализованная EBITDA × мультипликатор минус чистый долг (дивидендов нет четвёртый год). Сверху — два опциона: вероятность × (стоимость дополнительного денежного потока − капзатраты). Маржа опционов собрана из явных вводных: цена − экспортная пошлина − добыча и НДПИ − транспорт. Долгосрочные долларовые потоки дисконтируются ставкой, очищенной от ожидаемого ослабления рубля.
A4: Синий — вводные (меняйте их), чёрный — формулы, зелёный — ссылки на другие листы, жёлтый — главные рычаги модели.
A6: Показатель | B6: Значение | C6: Ед. | D6: Источник / комментарий
A7: ВВОДНЫЕ
A8: Нормализованная EBITDA (без опционов) | B8: 3350 | C8: млрд ₽ | D8: LTM на 30.06.2026: 3 348 млрд; 2025: 2 920 млрд; 1П 2026: 1 977 млрд, но 1П сезонно сильнее (53% EBITDA 2025). В июне 2026 компания ждала +6–7% за 2026 (~3,1 трлн). Берём LTM.
A9: Справедливый EV/EBITDA | B9: 2.5 | C9: x | D9: Исторически 2,5–3,5x, но при дивидендах. Без выплат и с убыточным газовым сегментом — нижняя граница.
A10: Скорр. чистый долг | B10: 6055 | C10: млрд ₽ | D10: На 30.06.2026, ЧД/EBITDA 1,81x (The Moscow Times, Fomag).
A11: Акций выпущено | B11: 23.674 | C11: млрд шт | D11: 23,674 млрд; × 114,75 ₽ = 2 716 млрд ₽ капитализации; казначейских акций на 31.12.2025 не было.
A12: Доли меньшинства в «дочках» (рыночная оценка) | B12: 360 | C12: млрд ₽ | D12: EBITDA консолидированная, поэтому чужие доли вычитаем: 4,3% «Газпром нефти» (~117 млрд по рынку), 22,5% «Сахалинской Энерджи» (~205 млрд на дату покупки), миноритарии Мосэнерго, ТГК-1, ОГК-2 (~40 млрд). Оценка модели — уточнить по МСФО.
A13: Доли в ассоциированных компаниях и СП | B13: 520 | C13: млрд ₽ | D13: Их прибыли нет в EBITDA: «Славнефть», «Арктикгаз», «Мессояха» и др. Балансовая стоимость 1 297 млрд (30.09.2024, МСФО); берём 0,4 баланса — дисконт, как у самой «Газпром нефти» (~0,6x). Оценка модели.
A14: Ставка дисконтирования (рубли) | B14: =Параметры!$B$9 -> 0.19 | C14: % | D14: Из «Параметров».
A15: Курс USD/RUB | B15: =Параметры!$B$13 -> 85 | C15: ₽ | D15: Из «Параметров».
A16: Ослабление рубля в год (долгосрочно) | B16: 0.04 | C16: % | D16: Разница инфляций РФ и США. Без неё 30-летние долларовые потоки по постоянному курсу дисконтировались бы рублёвой ставкой — это занижало опционы.
A17: Налог на прибыль | B17: 0.25 | C17: % | D17: С 2025 года 25%.
A18: Экспортная пошлина на трубопроводный газ | B18: 0.3 | C18: % | D18: 30% от цены — для Европы и Китая (льгота для поставок в Китай была только по НДПИ восточных месторождений).
A19: Добыча + НДПИ, $/тыс. м³ | B19: 40 | C19: $ | D19: Западная Сибирь, стандартный НДПИ ~2 400 ₽/тыс. м³ (~$28) + подъём газа ~$10–12. Оценка модели.
A20: «Северные потоки»: вероятность перезапуска | B20: 0.15 | C20: % | D20: NYT 17.10.2026: США видят перезапуск частью мирного плана; европейские переговорщики против, запрет на российский газ закреплён в законе ЕС (вступил 03.02.2026). Оценка модели — 15%.
A21: «Северные потоки»: объём, млрд м³ в год | B21: 27.5 | C21: млрд м³ | D21: Цела одна нитка «Северного потока — 2» (27,5 млрд м³); обе нитки СП-1 и нитка A СП-2 повреждены в 2022.
A22: «Северные потоки»: цена в Европе, $/тыс. м³ | B22: 300 | C22: $ | D22: Материалы бюджета: прочие покупатели $562 в 2026 (пик TTF), $362 в 2028, $323 в 2029. После возврата российского газа цены снизятся — берём $300.
A23: «Северные потоки»: транспорт до Балтики, $/тыс. м³ | B23: 20 | C23: $ | D23: Существующая ГТС ~3 000 км и своя труба: только операционные расходы и топливный газ.
A24: «Северные потоки»: лет до запуска | B24: 2 | C24: лет | D24: Нужны мирное соглашение, отмена запрета ЕС и проверка трубы.
A25: «Северные потоки»: капзатраты на ввод | B25: 50 | C25: млрд ₽ | D25: Инспекция и подключение уцелевшей нитки; оценка модели.
A26: «Северные потоки»: когда тратить, лет | B26: 1 | C26: лет
A27: «Сила Байкала»: вероятность подписания контракта | B27: 0.5 | C27: % | D27: Бывшая «Сила Сибири-2», переименована в 2026. Новак 21.10.2026: Газпром и CNPC могут согласовать коммерческие условия до конца года; цена и финансирование не решены.
A28: «Сила Байкала»: объём, млрд м³ в год | B28: 50 | C28: млрд м³ | D28: Проектная мощность 50 млрд м³ в год, маршрут через Монголию.
A29: «Сила Байкала»: цена для Китая, $/тыс. м³ | B29: 247.9 | C29: $ | D29: Как по «Силе Сибири» (решение пользователя). Материалы бюджета (ТАСС, 02.10.2026): 2025 — $240,3; 2026 — $247,9; 2027 — $251,3; 2028 — $247,8; 2029 — $246,4. Риск: по FT, Китай добивается намного более низкой цены.
A30: «Сила Байкала»: транспорт и транзит Монголии, $/тыс. м³ | B30: 25 | C30: $ | D30: ~3 500 км новой трубы: топливный газ и обслуживание ~$10–15 + транзит через Монголию ~$10–15 (тариф не раскрыт). Стройка трубы — отдельно, в капзатратах.
A31: «Сила Байкала»: срок контракта, лет | B31: 30 | C31: лет | D31: Как у «Силы Сибири-1» (30 лет).
A32: «Сила Байкала»: лет до полных объёмов | B32: 7.5 | C32: лет | D32: Первый газ ~2031, плато не раньше 2034–2035 (The Moscow Times, 24.04.2026); с учётом разгона — эквивалент полных объёмов с ~2033.
A33: «Сила Байкала»: капзатраты | B33: 1000 | C33: млрд ₽ | D33: Предварительная официальная оценка ~1 трлн ₽; критики (Крутихин, The Moscow Times 18.09.2026) считают её заниженной. См. точку окупаемости ниже.
A34: «Сила Байкала»: середина стройки, лет | B34: 4 | C34: лет | D34: Строительство ~2028–2032.
A35: Мир: вероятность мира и снятия санкций | B35: =Параметры!$B$15 -> 0.5 | C35: % | D35: Из «Параметров».
A36: Мир: лет до снятия санкций | B36: =Параметры!$B$16 -> 5 | C36: лет | D36: Из «Параметров».
A37: Мир: EV/EBITDA как до 2022 года | B37: 3.2 | C37: x | D37: Газпром в 2017–2021 стоил ~3–3,5x EBITDA (при дивидендах).
A38: Мир: вероятность запуска «Северных потоков» после мира | B38: 0.6 | C38: % | D38: Если санкции сняты, снят и запрет ЕС на российский газ. Но Европа перешла на СПГ и решение политическое — берём 60%.
A39: Мир: рост показателя до года мира, % в год | B39: 0.04 | C39: % | D39: Рост EBITDA в среднем за 5 лет.
A41: РАСЧЁТ
A42: Справедливая стоимость бизнеса (EV), база | B42: =$B$8*$B$9 -> 8375 | C42: млрд ₽
...

Sheet NLMK
A1: NLMK — НЛМК: модель справедливой стоимости
A2: Метод: EV/EBITDA на нормализованную (среднецикличную) EBITDA с дисконтом за ожидание
A3: Металлург на дне цикла: текущая EBITDA занижена, оценивать по ней — продать на дне. Берём EBITDA «нормального» года (выручка × среднецикличная маржа), умножаем на мультипликатор, дисконтируем за годы до восстановления спроса и прибавляем чистый кэш.
A4: Синий — вводные (меняйте их), чёрный — формулы, зелёный — ссылки на другие листы, жёлтый — главные рычаги модели.
A6: Показатель | B6: Значение | C6: Ед. | D6: Источник / комментарий
A7: ВВОДНЫЕ
A8: Выручка нормального года | B8: 830 | C8: млрд ₽ | D8: 2025: 831,4 млрд (−15%); LTM на 30.06.2026: 780 млрд. Берём уровень 2025 — без расчёта на возврат к пику 2021–2022.
A9: Среднецикличная маржа EBITDA | B9: 0.2 | C9: % | D9: 2024 ≈ 26%, 2025 — 16,9%, 1П 2026 — 14,8% (дно). Берём 20% — середину, ниже исторических 25–30% из‑за потери экспорта.
A10: Справедливый EV/EBITDA | B10: 4 | C10: x | D10: До 2022 НЛМК стоил 5–6x при выплате 100% FCF; сейчас дивидендов нет два года подряд — дисконт до 4x.
A11: Ставка дисконтирования | B11: =Параметры!$B$9 -> 0.19 | C11: % | D11: Из «Параметров».
A12: Лет до восстановления спроса | B12: 1.5 | C12: лет | D12: НКР: восстановление спроса не раньше 2П 2027, заметное — в 2028; Т-Инвестиции допускают, что 2026 — дно.
A13: Чистый долг (минус = чистый кэш) | B13: -40.7 | C13: млрд ₽ | D13: На 30.06.2026: кэш 80,3 млрд, долг 39,7 млрд (МСФО 1П 2026).
A14: Акций в обращении | B14: 5.9932 | C14: млрд шт | D14: 5 993 227 240 акций; 5,993 × 76,38 ₽ = 457,8 млрд ₽ капитализации.
A15: EBITDA 2026П (для проверки) | B15: 115 | C15: млрд ₽ | D15: 1П 2026: 57,2 млрд × 2.
A16: Мир: вероятность мира и снятия санкций | B16: =Параметры!$B$15 -> 0.5 | C16: % | D16: Из «Параметров».
A17: Мир: лет до снятия санкций | B17: =Параметры!$B$16 -> 5 | C17: лет | D17: Из «Параметров».
A18: Мир: EV/EBITDA как до 2022 года | B18: 5.5 | C18: x | D18: НЛМК в 2017–2021 стоил ~5–6x EBITDA при выплате 100% FCF.
A19: Мир: маржа EBITDA после снятия санкций | B19: 0.24 | C19: % | D19: До 2022 маржа EBITDA НЛМК была 25–30%; после снятия санкций возвращается экспорт в ЕС и США. Берём 24%.
A20: Мир: рост показателя до года мира, % в год | B20: 0.05 | C20: % | D20: Рост выручки и EBITDA в среднем за 5 лет.
A22: РАСЧЁТ
A23: Нормализованная EBITDA | B23: =$B$8*$B$9 -> 166 | C23: млрд ₽
A24: Стоимость бизнеса в нормальный год | B24: =$B$23*$B$10 -> 664 | C24: млрд ₽
A25: Стоимость бизнеса сегодня (дисконт за ожидание) | B25: =$B$24/(1+$B$11)^$B$12 -> 511.50235 | C25: млрд ₽
A26: Стоимость акционерного капитала | B26: =$B$25-$B$13 -> 552.20235 | C26: млрд ₽
A27: Справедливая цена без мира | B27: =IF($B$14>0,$B$26/$B$14,0) -> 92.138149 | C27: ₽
A28: Мир: цена в мирном режиме на сегодняшних показателях | B28: =($B$8*$B$19*$B$18/(1+$B$11)^$B$12-$B$13)/$B$14 -> 147.61378 | C28: ₽ | D28: Если бы рынок уже сегодня оценивал компанию как до 2022 года.
A29: Мир: прибавка к цене сегодня | B29: =$B$16*($B$28-$B$27)*((1+$B$20)/(1+$B$11))^$B$17 -> 14.834876 | C29: ₽ | D29: Вероятность × разница цен × рост показателя до года мира, приведённый к сегодняшнему дню.
A30: Справедливая цена с миром | B30: =$B$27+$B$29 -> 106.97302 | C30: ₽
A32: РЕЗУЛЬТАТ
A33: Справедливая цена | B33: =$B$30 -> 106.97302 | C33: ₽ | D33: Главный вывод модели
A34: Текущая цена | B34: =Сводка!$D$12 -> 76.44 | C34: ₽ | D34: Берётся со «Сводки» (столбец D)
A35: Зона покупки: цена не выше | B35: =$B$33*(1-Параметры!$B$10) -> 82.369229 | C35: ₽ | D35: Справедливая минус скидка из «Параметров»
A36: Цена продажи | B36: =$B$33*(1+Параметры!$B$11) -> 126.22817 | C36: ₽ | D36: Справедливая плюс премия из «Параметров»
A37: Сигнал «приближается к продаже» от | B37: =$B$36*(1-Параметры!$B$12) -> 119.91676 | C37: ₽ | D37: За сколько % до цены продажи бот предупреждает
A38: Потенциал до справедливой | B38: =IF($B$34>0,$B$33/$B$34-1,0) -> 0.39943779 | C38: %
A39: До цены продажи | B39: =IF($B$34>0,$B$36/$B$34-1,0) -> 0.65133659 | C39: %
A40: Статус | B40: =IF($B$34<=$B$35,"ЗОНА ПОКУПКИ",IF($B$34>=$B$36,"ЦЕНА ПРОДАЖИ",IF($B$34>=$B$37,"ПРИБЛИЖАЕТСЯ К ПРОДАЖЕ","ДЕРЖАТЬ"))) -> ЗОНА ПОКУПКИ | D40: Слом тезиса — отдельный сигнал, см. ниже
A42: ПЕРЕКРЁСТНАЯ ПРОВЕРКА
A43: EV/EBITDA 2026П при текущей цене | B43: =IF($B$15>0,($B$34*$B$14+$B$13)/$B$15,0) -> 3.6297409 | C43: x | D43: Рынок уже платит ~3,6x даже за дно цикла.
A44: EV/нормализованная EBITDA при текущей цене | B44: =IF($B$23>0,($B$34*$B$14+$B$13)/$B$23,0) -> 2.5145796 | C44: x
...

Sheet BSPB
A1: BSPB — Банк Санкт-Петербург: модель справедливой стоимости
A2: Метод: дивидендная модель (формула Гордона)
A3: Для справки: позиции в портфеле нет. Банк платит 50% прибыли по МСФО дважды в год, поэтому стоимость акции = дивиденд / (требуемая доходность − рост дивиденда). Проверка — P/E и ROE против истории банка.
A4: Синий — вводные (меняйте их), чёрный — формулы, зелёный — ссылки на другие листы, жёлтый — главные рычаги модели.
A6: Показатель | B6: Значение | C6: Ед. | D6: Источник / комментарий
A7: ВВОДНЫЕ
A8: Чистая прибыль 2026П (МСФО) | B8: 30 | C8: млрд ₽ | D8: Менеджмент снизил прогноз с 35 до 30 млрд (август 2026); 1П 2026 МСФО: 16,5 млрд (−33% г/г); 9М 2026 РСБУ: 24,3 млрд после налога. Прибыль падает вместе со ставкой: у банка много дешёвых остатков на счетах.
A9: Доля прибыли на дивиденды | B9: 0.5 | C9: % | D9: Политика: 20–50% прибыли МСФО; фактически платит 50% (за 1П 2026 — 19,17 ₽, за 2П 2025 — 26,23 ₽).
A10: Обыкновенных акций в обращении | B10: 0.4454 | C10: млрд шт | D10: ~445,4 млн (investmint, капитализация 114,4 млрд ₽ при 257 ₽). Привилегированные получают символические 0,22 ₽ и не учитываются.
A11: Базовая требуемая доходность | B11: =Параметры!$B$9 -> 0.19 | C11: % | D11: Из «Параметров»: ставка ЦБ 2027 + премия за риск акций.
A12: Премия за специфический риск | B12: 0.01 | C12: % | D12: Региональный банк с контролирующим акционером; аналитики отмечают рост рисков у небольших банков при жёсткой ДКП (Freedom, август 2026).
A13: Долгосрочный рост дивиденда | B13: 0.06 | C13: % | D13: Устойчивый рост ≈ ROE ~14% × нераспределённая прибыль 50% ≈ 7%; берём 6%.
A14: Собственный капитал (для проверки) | B14: 223.4 | C14: млрд ₽ | D14: На 01.10.2026 по РСБУ (Фонтанка); по МСФО на 30.06.2026 — 218,4 млрд.
A15: Мир: вероятность мира и снятия санкций | B15: =Параметры!$B$15 -> 0.5 | C15: % | D15: Из «Параметров».
A16: Мир: лет до снятия санкций | B16: =Параметры!$B$16 -> 5 | C16: лет | D16: Из «Параметров».
A17: Мир: P/E как до 2022 года | B17: 4.5 | C17: x | D17: В 2019–2021 банк стоил ~3,5–4,5 годовые прибыли при ROE 10–12%. Берём 4,5x.
A18: Мир: рост показателя до года мира, % в год | B18: 0.06 | C18: % | D18: Как рост дивиденда.
A20: РАСЧЁТ
A21: Дивиденд за 2026 (1П выплачен, 2П — весной 2027) | B21: =$B$8*$B$9/$B$10 -> 33.677593 | C21: ₽/акц.
A22: Требуемая доходность | B22: =$B$11+$B$12 -> 0.2 | C22: %
A23: Справедливая дивдоходность (r − g) | B23: =$B$22-$B$13 -> 0.14 | C23: %
A24: Справедливая цена без мира | B24: =IF($B$23>0,$B$21/$B$23,0) -> 240.55424 | C24: ₽
A25: Мир: цена в мирном режиме на сегодняшних показателях | B25: =$B$17*$B$8/$B$10 -> 303.09834 | C25: ₽ | D25: Если бы рынок уже сегодня оценивал компанию как до 2022 года.
A26: Мир: прибавка к цене сегодня | B26: =$B$15*($B$25-$B$24)*((1+$B$18)/(1+$B$11))^$B$16 -> 17.536822 | C26: ₽ | D26: Вероятность × разница цен × рост показателя до года мира, приведённый к сегодняшнему дню.
A27: Справедливая цена с миром | B27: =$B$24+$B$26 -> 258.09106 | C27: ₽
A29: РЕЗУЛЬТАТ
A30: Справедливая цена | B30: =$B$27 -> 258.09106 | C30: ₽ | D30: Главный вывод модели
A31: Текущая цена | B31: =Сводка!$D$13 -> 257.06 | C31: ₽ | D31: Берётся со «Сводки» (столбец D)
A32: Зона покупки: цена не выше | B32: =$B$30*(1-Параметры!$B$10) -> 198.73012 | C32: ₽ | D32: Справедливая минус скидка из «Параметров»
A33: Цена продажи | B33: =$B$30*(1+Параметры!$B$11) -> 304.54745 | C33: ₽ | D33: Справедливая плюс премия из «Параметров»
A34: Сигнал «приближается к продаже» от | B34: =$B$33*(1-Параметры!$B$12) -> 289.32008 | C34: ₽ | D34: За сколько % до цены продажи бот предупреждает
A35: Потенциал до справедливой | B35: =IF($B$31>0,$B$30/$B$31-1,0) -> 0.0040109644 | C35: %
A36: До цены продажи | B36: =IF($B$31>0,$B$33/$B$31-1,0) -> 0.18473294 | C36: %
A37: Статус | B37: =IF($B$31<=$B$32,"ЗОНА ПОКУПКИ",IF($B$31>=$B$33,"ЦЕНА ПРОДАЖИ",IF($B$31>=$B$34,"ПРИБЛИЖАЕТСЯ К ПРОДАЖЕ","ДЕРЖАТЬ"))) -> ДЕРЖАТЬ | D37: Слом тезиса — отдельный сигнал, см. ниже
A39: ПЕРЕКРЁСТНАЯ ПРОВЕРКА
A40: Прибыль на акцию 2026П | B40: =$B$8/$B$10 -> 67.355186 | C40: ₽
A41: P/E при справедливой цене | B41: =IF($B$40>0,$B$30/$B$40,0) -> 3.8317919 | C41: x | D41: Исторически банк стоил 3–4,5 годовые прибыли.
A42: ROE 2026П | B42: =IF($B$14>0,$B$8/$B$14,0) -> 0.13428827 | C42: % | D42: В 2023–2024 было 25%+; падает вместе со ставкой.
A43: Дивдоходность к текущей цене | B43: =IF($B$31>0,$B$21/$B$31,0) -> 0.13101063 | C43: %
A44: Доходность, которую закладывает текущая цена (D/P + g) | B44: =IF($B$31>0,$B$21/$B$31+$B$13,0) -> 0.19101063 | C44: % | D44: Сравните с длинными ОФЗ 16,6%.
...

Sheet Журнал
A1: Журнал изменений оценок
A2: Каждое изменение справедливой цены — с причиной и источником. Изменения больше 10% бот только предлагает, применяете вы.
A4: Дата | B4: Тикер | C4: Что изменилось | D4: Было | E4: Стало | F4: Справедливая после, ₽ | G4: Причина | H4: Источник | I4: Кто
A5: 24.10.2026 | B5: SBER | C5: Модель создана | F5: 392.42 | G5: Первичная оценка: Дивиденды (Гордон). | I5: Claude
A6: 24.10.2026 | B6: PLZL | C6: Модель создана | F6: 1228.95 | G6: Первичная оценка: EV/EBITDA от золота. | I6: Claude
A7: 24.10.2026 | B7: POSI | C7: Модель создана | F7: 1381.75 | G7: Первичная оценка: P/E на NIC 2027П. | I7: Claude
A8: 24.10.2026 | B8: PRMD | C8: Модель создана | F8: 608.19 | G8: Первичная оценка: EV/EBITDA 2027П. | I8: Claude
A9: 24.10.2026 | B9: YDEX | C9: Модель создана | F9: 4646.97 | G9: Первичная оценка: EV/EBITDA 2027П. | I9: Claude
A10: 24.10.2026 | B10: MTSS | C10: Модель создана | F10: 206.05 | G10: Первичная оценка: Выплаты акционерам (Гордон). | I10: Claude
A11: 24.10.2026 | B11: GAZP | C11: Модель создана | F11: 111.79 | G11: Первичная оценка: EV/EBITDA + опционы. | I11: Claude
